[2023-11-26T05:30:59.732+0000] {logging_mixin.py:154} INFO - Changing /opt/***/logs/dag_id=outcomes_dag1/run_id=scheduled__2023-11-25T00:00:00+00:00/task_id=EXTRACT_DATA_FROM_API_TO_GCP permission to 509
[2023-11-26T05:30:59.808+0000] {logging_mixin.py:154} INFO - Changing /opt/***/logs/dag_id=outcomes_dag1/run_id=scheduled__2023-11-25T00:00:00+00:00/task_id=EXTRACT_DATA_FROM_API_TO_GCP permission to 509
[2023-11-26T05:30:59.874+0000] {taskinstance.py:1159} INFO - Dependencies all met for dep_context=non-requeueable deps ti=<TaskInstance: outcomes_dag1.EXTRACT_DATA_FROM_API_TO_GCP scheduled__2023-11-25T00:00:00+00:00 [queued]>
[2023-11-26T05:30:59.909+0000] {taskinstance.py:1159} INFO - Dependencies all met for dep_context=requeueable deps ti=<TaskInstance: outcomes_dag1.EXTRACT_DATA_FROM_API_TO_GCP scheduled__2023-11-25T00:00:00+00:00 [queued]>
[2023-11-26T05:30:59.913+0000] {taskinstance.py:1361} INFO - Starting attempt 1 of 2
[2023-11-26T05:31:00.332+0000] {taskinstance.py:1382} INFO - Executing <Task(PythonOperator): EXTRACT_DATA_FROM_API_TO_GCP> on 2023-11-25 00:00:00+00:00
[2023-11-26T05:31:00.345+0000] {standard_task_runner.py:57} INFO - Started process 335 to run task
[2023-11-26T05:31:00.358+0000] {standard_task_runner.py:84} INFO - Running: ['***', 'tasks', 'run', 'outcomes_dag1', 'EXTRACT_DATA_FROM_API_TO_GCP', 'scheduled__2023-11-25T00:00:00+00:00', '--job-id', '13', '--raw', '--subdir', 'DAGS_FOLDER/Retry2.py', '--cfg-path', '/tmp/tmpskjaad4p']
[2023-11-26T05:31:00.368+0000] {standard_task_runner.py:85} INFO - Job 13: Subtask EXTRACT_DATA_FROM_API_TO_GCP
[2023-11-26T05:31:00.590+0000] {logging_mixin.py:154} INFO - Changing /opt/***/logs/dag_id=outcomes_dag1/run_id=scheduled__2023-11-25T00:00:00+00:00/task_id=EXTRACT_DATA_FROM_API_TO_GCP permission to 509
[2023-11-26T05:31:00.604+0000] {task_command.py:416} INFO - Running <TaskInstance: outcomes_dag1.EXTRACT_DATA_FROM_API_TO_GCP scheduled__2023-11-25T00:00:00+00:00 [running]> on host 42136bd2bf4d
[2023-11-26T05:31:00.929+0000] {taskinstance.py:1662} INFO - Exporting env vars: AIRFLOW_CTX_DAG_OWNER='***' AIRFLOW_CTX_DAG_ID='outcomes_dag1' AIRFLOW_CTX_TASK_ID='EXTRACT_DATA_FROM_API_TO_GCP' AIRFLOW_CTX_EXECUTION_DATE='2023-11-25T00:00:00+00:00' AIRFLOW_CTX_TRY_NUMBER='1' AIRFLOW_CTX_DAG_RUN_ID='scheduled__2023-11-25T00:00:00+00:00'
[2023-11-26T05:31:04.392+0000] {logging_mixin.py:154} INFO - response :  <Response [200]>
[2023-11-26T05:31:06.436+0000] {logging_mixin.py:154} INFO - response :  <Response [200]>
[2023-11-26T05:31:08.745+0000] {logging_mixin.py:154} INFO - response :  <Response [200]>
[2023-11-26T05:31:10.228+0000] {logging_mixin.py:154} INFO - response :  <Response [200]>
[2023-11-26T05:31:13.423+0000] {logging_mixin.py:154} INFO - Writing data to GCS.....
[2023-11-26T05:32:16.172+0000] {taskinstance.py:1937} ERROR - Task failed with exception
Traceback (most recent call last):
  File "/home/airflow/.local/lib/python3.8/site-packages/urllib3/connectionpool.py", line 715, in urlopen
    httplib_response = self._make_request(
  File "/home/airflow/.local/lib/python3.8/site-packages/urllib3/connectionpool.py", line 416, in _make_request
    conn.request(method, url, **httplib_request_kw)
  File "/home/airflow/.local/lib/python3.8/site-packages/urllib3/connection.py", line 244, in request
    super(HTTPConnection, self).request(method, url, body=body, headers=headers)
  File "/usr/local/lib/python3.8/http/client.py", line 1256, in request
    self._send_request(method, url, body, headers, encode_chunked)
  File "/usr/local/lib/python3.8/http/client.py", line 1302, in _send_request
    self.endheaders(body, encode_chunked=encode_chunked)
  File "/usr/local/lib/python3.8/http/client.py", line 1251, in endheaders
    self._send_output(message_body, encode_chunked=encode_chunked)
  File "/usr/local/lib/python3.8/http/client.py", line 1050, in _send_output
    self.send(chunk)
  File "/usr/local/lib/python3.8/http/client.py", line 972, in send
    self.sock.sendall(data)
  File "/usr/local/lib/python3.8/ssl.py", line 1237, in sendall
    v = self.send(byte_view[count:])
  File "/usr/local/lib/python3.8/ssl.py", line 1206, in send
    return self._sslobj.write(data)
socket.timeout: The write operation timed out

During handling of the above exception, another exception occurred:

Traceback (most recent call last):
  File "/home/airflow/.local/lib/python3.8/site-packages/requests/adapters.py", line 486, in send
    resp = conn.urlopen(
  File "/home/airflow/.local/lib/python3.8/site-packages/urllib3/connectionpool.py", line 799, in urlopen
    retries = retries.increment(
  File "/home/airflow/.local/lib/python3.8/site-packages/urllib3/util/retry.py", line 550, in increment
    raise six.reraise(type(error), error, _stacktrace)
  File "/home/airflow/.local/lib/python3.8/site-packages/urllib3/packages/six.py", line 769, in reraise
    raise value.with_traceback(tb)
  File "/home/airflow/.local/lib/python3.8/site-packages/urllib3/connectionpool.py", line 715, in urlopen
    httplib_response = self._make_request(
  File "/home/airflow/.local/lib/python3.8/site-packages/urllib3/connectionpool.py", line 416, in _make_request
    conn.request(method, url, **httplib_request_kw)
  File "/home/airflow/.local/lib/python3.8/site-packages/urllib3/connection.py", line 244, in request
    super(HTTPConnection, self).request(method, url, body=body, headers=headers)
  File "/usr/local/lib/python3.8/http/client.py", line 1256, in request
    self._send_request(method, url, body, headers, encode_chunked)
  File "/usr/local/lib/python3.8/http/client.py", line 1302, in _send_request
    self.endheaders(body, encode_chunked=encode_chunked)
  File "/usr/local/lib/python3.8/http/client.py", line 1251, in endheaders
    self._send_output(message_body, encode_chunked=encode_chunked)
  File "/usr/local/lib/python3.8/http/client.py", line 1050, in _send_output
    self.send(chunk)
  File "/usr/local/lib/python3.8/http/client.py", line 972, in send
    self.sock.sendall(data)
  File "/usr/local/lib/python3.8/ssl.py", line 1237, in sendall
    v = self.send(byte_view[count:])
  File "/usr/local/lib/python3.8/ssl.py", line 1206, in send
    return self._sslobj.write(data)
urllib3.exceptions.ProtocolError: ('Connection aborted.', timeout('The write operation timed out'))

During handling of the above exception, another exception occurred:

Traceback (most recent call last):
  File "/home/airflow/.local/lib/python3.8/site-packages/airflow/operators/python.py", line 192, in execute
    return_value = self.execute_callable()
  File "/home/airflow/.local/lib/python3.8/site-packages/airflow/operators/python.py", line 209, in execute_callable
    return self.python_callable(*self.op_args, **self.op_kwargs)
  File "/opt/airflow/dags/ExtractTransformLoad_Steps/ExtractAPItoGCP.py", line 104, in main
    upload_to_gcs(shelter_data, gcs_bucket_name, gcs_file_path)
  File "/opt/airflow/dags/ExtractTransformLoad_Steps/ExtractAPItoGCP.py", line 93, in upload_to_gcs
    blob.upload_from_string(csv_df, content_type='text/csv')
  File "/home/airflow/.local/lib/python3.8/site-packages/google/cloud/storage/blob.py", line 3056, in upload_from_string
    self.upload_from_file(
  File "/home/airflow/.local/lib/python3.8/site-packages/google/cloud/storage/blob.py", line 2763, in upload_from_file
    self._prep_and_do_upload(
  File "/home/airflow/.local/lib/python3.8/site-packages/google/cloud/storage/blob.py", line 2604, in _prep_and_do_upload
    created_json = self._do_upload(
  File "/home/airflow/.local/lib/python3.8/site-packages/google/cloud/storage/blob.py", line 2427, in _do_upload
    response = self._do_resumable_upload(
  File "/home/airflow/.local/lib/python3.8/site-packages/google/cloud/storage/blob.py", line 2263, in _do_resumable_upload
    response = upload.transmit_next_chunk(transport, timeout=timeout)
  File "/home/airflow/.local/lib/python3.8/site-packages/google/resumable_media/requests/upload.py", line 515, in transmit_next_chunk
    return _request_helpers.wait_and_retry(
  File "/home/airflow/.local/lib/python3.8/site-packages/google/resumable_media/requests/_request_helpers.py", line 178, in wait_and_retry
    raise error
  File "/home/airflow/.local/lib/python3.8/site-packages/google/resumable_media/requests/_request_helpers.py", line 155, in wait_and_retry
    response = func()
  File "/home/airflow/.local/lib/python3.8/site-packages/google/resumable_media/requests/upload.py", line 507, in retriable_request
    result = transport.request(
  File "/home/airflow/.local/lib/python3.8/site-packages/google/auth/transport/requests.py", line 542, in request
    response = super(AuthorizedSession, self).request(
  File "/home/airflow/.local/lib/python3.8/site-packages/requests/sessions.py", line 589, in request
    resp = self.send(prep, **send_kwargs)
  File "/home/airflow/.local/lib/python3.8/site-packages/requests/sessions.py", line 703, in send
    r = adapter.send(request, **kwargs)
  File "/home/airflow/.local/lib/python3.8/site-packages/requests/adapters.py", line 501, in send
    raise ConnectionError(err, request=request)
requests.exceptions.ConnectionError: ('Connection aborted.', timeout('The write operation timed out'))
[2023-11-26T05:32:16.210+0000] {taskinstance.py:1400} INFO - Marking task as UP_FOR_RETRY. dag_id=outcomes_dag1, task_id=EXTRACT_DATA_FROM_API_TO_GCP, execution_date=20231125T000000, start_date=20231126T053059, end_date=20231126T053216
[2023-11-26T05:32:16.228+0000] {standard_task_runner.py:104} ERROR - Failed to execute job 13 for task EXTRACT_DATA_FROM_API_TO_GCP (('Connection aborted.', timeout('The write operation timed out')); 335)
[2023-11-26T05:32:16.268+0000] {local_task_job_runner.py:228} INFO - Task exited with return code 1
[2023-11-26T05:32:16.298+0000] {taskinstance.py:2778} INFO - 0 downstream tasks scheduled from follow-on schedule check
