[2023-11-26T06:37:22.899+0000] {logging_mixin.py:154} INFO - Changing /opt/***/logs/dag_id=outcomes_dag/run_id=manual__2023-11-26T06:35:39.961902+00:00/task_id=LOAD_DIMENSION_OUTCOME_TYPES permission to 509
[2023-11-26T06:37:22.955+0000] {logging_mixin.py:154} INFO - Changing /opt/***/logs/dag_id=outcomes_dag/run_id=manual__2023-11-26T06:35:39.961902+00:00/task_id=LOAD_DIMENSION_OUTCOME_TYPES permission to 509
[2023-11-26T06:37:23.003+0000] {taskinstance.py:1159} INFO - Dependencies all met for dep_context=non-requeueable deps ti=<TaskInstance: outcomes_dag.LOAD_DIMENSION_OUTCOME_TYPES manual__2023-11-26T06:35:39.961902+00:00 [queued]>
[2023-11-26T06:37:23.031+0000] {taskinstance.py:1159} INFO - Dependencies all met for dep_context=requeueable deps ti=<TaskInstance: outcomes_dag.LOAD_DIMENSION_OUTCOME_TYPES manual__2023-11-26T06:35:39.961902+00:00 [queued]>
[2023-11-26T06:37:23.034+0000] {taskinstance.py:1361} INFO - Starting attempt 1 of 2
[2023-11-26T06:37:23.313+0000] {taskinstance.py:1382} INFO - Executing <Task(PythonOperator): LOAD_DIMENSION_OUTCOME_TYPES> on 2023-11-26 06:35:39.961902+00:00
[2023-11-26T06:37:23.332+0000] {standard_task_runner.py:57} INFO - Started process 1432 to run task
[2023-11-26T06:37:23.337+0000] {standard_task_runner.py:84} INFO - Running: ['***', 'tasks', 'run', 'outcomes_dag', 'LOAD_DIMENSION_OUTCOME_TYPES', 'manual__2023-11-26T06:35:39.961902+00:00', '--job-id', '51', '--raw', '--subdir', 'DAGS_FOLDER/outcomes_dag.py', '--cfg-path', '/tmp/tmpxepz5_1y']
[2023-11-26T06:37:23.341+0000] {standard_task_runner.py:85} INFO - Job 51: Subtask LOAD_DIMENSION_OUTCOME_TYPES
[2023-11-26T06:37:23.435+0000] {logging_mixin.py:154} INFO - Changing /opt/***/logs/dag_id=outcomes_dag/run_id=manual__2023-11-26T06:35:39.961902+00:00/task_id=LOAD_DIMENSION_OUTCOME_TYPES permission to 509
[2023-11-26T06:37:23.442+0000] {task_command.py:416} INFO - Running <TaskInstance: outcomes_dag.LOAD_DIMENSION_OUTCOME_TYPES manual__2023-11-26T06:35:39.961902+00:00 [running]> on host 42136bd2bf4d
[2023-11-26T06:37:23.574+0000] {taskinstance.py:1662} INFO - Exporting env vars: AIRFLOW_CTX_DAG_OWNER='***' AIRFLOW_CTX_DAG_ID='outcomes_dag' AIRFLOW_CTX_TASK_ID='LOAD_DIMENSION_OUTCOME_TYPES' AIRFLOW_CTX_EXECUTION_DATE='2023-11-26T06:35:39.961902+00:00' AIRFLOW_CTX_TRY_NUMBER='1' AIRFLOW_CTX_DAG_RUN_ID='manual__2023-11-26T06:35:39.961902+00:00'
[2023-11-26T06:37:23.932+0000] {taskinstance.py:1937} ERROR - Task failed with exception
Traceback (most recent call last):
  File "/home/airflow/.local/lib/python3.8/site-packages/airflow/operators/python.py", line 192, in execute
    return_value = self.execute_callable()
  File "/home/airflow/.local/lib/python3.8/site-packages/airflow/operators/python.py", line 209, in execute_callable
    return self.python_callable(*self.op_args, **self.op_kwargs)
  File "/opt/airflow/dags/etlscripts/LoadData.py", line 145, in load_data_to_postgres
    table_data_df = gcp_loader.get_data(file_name)
  File "/opt/airflow/dags/etlscripts/LoadData.py", line 43, in get_data
    df = self.connect_to_gcp_and_get_data(file_name)
  File "/opt/airflow/dags/etlscripts/LoadData.py", line 34, in connect_to_gcp_and_get_data
    bucket = client.get_bucket(self.bucket_name)
  File "/home/airflow/.local/lib/python3.8/site-packages/google/cloud/storage/client.py", line 782, in get_bucket
    bucket.reload(
  File "/home/airflow/.local/lib/python3.8/site-packages/google/cloud/storage/bucket.py", line 1075, in reload
    super(Bucket, self).reload(
  File "/home/airflow/.local/lib/python3.8/site-packages/google/cloud/storage/_helpers.py", line 246, in reload
    api_response = client._get_resource(
  File "/home/airflow/.local/lib/python3.8/site-packages/google/cloud/storage/client.py", line 387, in _get_resource
    return self._connection.api_request(
  File "/home/airflow/.local/lib/python3.8/site-packages/google/cloud/storage/_http.py", line 72, in api_request
    return call()
  File "/home/airflow/.local/lib/python3.8/site-packages/google/api_core/retry.py", line 366, in retry_wrapped_func
    return retry_target(
  File "/home/airflow/.local/lib/python3.8/site-packages/google/api_core/retry.py", line 204, in retry_target
    return target()
  File "/home/airflow/.local/lib/python3.8/site-packages/google/cloud/_http/__init__.py", line 494, in api_request
    raise exceptions.from_http_response(response)
google.api_core.exceptions.Forbidden: 403 GET https://storage.googleapis.com/storage/v1/b/data_center_lab3?projection=noAcl&prettyPrint=false: akithap@plasma-backbone-406301.iam.gserviceaccount.com does not have storage.buckets.get access to the Google Cloud Storage bucket. Permission 'storage.buckets.get' denied on resource (or it may not exist).
[2023-11-26T06:37:23.970+0000] {taskinstance.py:1400} INFO - Marking task as UP_FOR_RETRY. dag_id=outcomes_dag, task_id=LOAD_DIMENSION_OUTCOME_TYPES, execution_date=20231126T063539, start_date=20231126T063723, end_date=20231126T063723
[2023-11-26T06:37:23.998+0000] {standard_task_runner.py:104} ERROR - Failed to execute job 51 for task LOAD_DIMENSION_OUTCOME_TYPES (403 GET https://storage.googleapis.com/storage/v1/b/data_center_lab3?projection=noAcl&prettyPrint=false: akithap@plasma-backbone-406301.iam.gserviceaccount.com does not have storage.buckets.get access to the Google Cloud Storage bucket. Permission 'storage.buckets.get' denied on resource (or it may not exist).; 1432)
[2023-11-26T06:37:24.036+0000] {local_task_job_runner.py:228} INFO - Task exited with return code 1
[2023-11-26T06:37:24.096+0000] {taskinstance.py:2778} INFO - 0 downstream tasks scheduled from follow-on schedule check
